[2023-12-05T14:25:36.215+0000] {taskinstance.py:1159} INFO - Dependencies all met for dep_context=non-requeueable deps ti=<TaskInstance: dag_with_hook_v4.upload_to_s3 scheduled__2023-12-04T03:00:00+00:00 [queued]>
[2023-12-05T14:25:36.232+0000] {taskinstance.py:1159} INFO - Dependencies all met for dep_context=requeueable deps ti=<TaskInstance: dag_with_hook_v4.upload_to_s3 scheduled__2023-12-04T03:00:00+00:00 [queued]>
[2023-12-05T14:25:36.233+0000] {taskinstance.py:1361} INFO - Starting attempt 2 of 6
[2023-12-05T14:25:36.255+0000] {taskinstance.py:1382} INFO - Executing <Task(PythonOperator): upload_to_s3> on 2023-12-04 03:00:00+00:00
[2023-12-05T14:25:36.264+0000] {standard_task_runner.py:57} INFO - Started process 18009 to run task
[2023-12-05T14:25:36.268+0000] {standard_task_runner.py:84} INFO - Running: ['***', 'tasks', 'run', 'dag_with_hook_v4', 'upload_to_s3', 'scheduled__2023-12-04T03:00:00+00:00', '--job-id', '360', '--raw', '--subdir', 'DAGS_FOLDER/dag_with_postgres_with_hook.py', '--cfg-path', '/tmp/tmp7qrzek3t']
[2023-12-05T14:25:36.274+0000] {standard_task_runner.py:85} INFO - Job 360: Subtask upload_to_s3
[2023-12-05T14:25:36.375+0000] {task_command.py:416} INFO - Running <TaskInstance: dag_with_hook_v4.upload_to_s3 scheduled__2023-12-04T03:00:00+00:00 [running]> on host 0c998a8be895
[2023-12-05T14:25:36.526+0000] {taskinstance.py:1662} INFO - Exporting env vars: AIRFLOW_CTX_DAG_OWNER='debora' AIRFLOW_CTX_DAG_ID='dag_with_hook_v4' AIRFLOW_CTX_TASK_ID='upload_to_s3' AIRFLOW_CTX_EXECUTION_DATE='2023-12-04T03:00:00+00:00' AIRFLOW_CTX_TRY_NUMBER='2' AIRFLOW_CTX_DAG_RUN_ID='scheduled__2023-12-04T03:00:00+00:00'
[2023-12-05T14:25:36.538+0000] {logging_mixin.py:154} WARNING - /home/***/.local/lib/python3.8/site-packages/***/utils/context.py:206 AirflowContextDeprecationWarning: Accessing 'execution_date' from the template is deprecated and will be removed in a future version. Please use 'data_interval_start' or 'logical_date' instead.
[2023-12-05T14:25:36.553+0000] {base.py:73} INFO - Using connection ID 'postgres_localhost' for task execution.
[2023-12-05T14:25:36.566+0000] {logging_mixin.py:154} INFO - connected to postgres
[2023-12-05T14:25:36.576+0000] {dag_with_postgres_with_hook.py:33} INFO - Saved get_orders_2023-12-04T03:00:00+00:00
[2023-12-05T14:25:36.592+0000] {base.py:73} INFO - Using connection ID 'minio_conn_id' for task execution.
[2023-12-05T14:25:36.593+0000] {connection_wrapper.py:381} INFO - AWS Connection (conn_id='minio_conn_id', conn_type='aws') credentials retrieved from extra.
[2023-12-05T14:25:36.596+0000] {logging_mixin.py:154} WARNING - <string>:9 AirflowProviderDeprecationWarning: extra['host'] is deprecated and will be removed in a future release. Please set extra['endpoint_url'] instead
[2023-12-05T14:25:37.364+0000] {taskinstance.py:1937} ERROR - Task failed with exception
Traceback (most recent call last):
  File "/home/airflow/.local/lib/python3.8/site-packages/airflow/operators/python.py", line 192, in execute
    return_value = self.execute_callable()
  File "/home/airflow/.local/lib/python3.8/site-packages/airflow/operators/python.py", line 209, in execute_callable
    return self.python_callable(*self.op_args, **self.op_kwargs)
  File "/opt/airflow/dags/dag_with_postgres_with_hook.py", line 35, in postgres_to_s3
    s3_hook.load_file(
  File "/home/airflow/.local/lib/python3.8/site-packages/airflow/providers/amazon/aws/hooks/s3.py", line 135, in wrapper
    return func(*bound_args.args, **bound_args.kwargs)
  File "/home/airflow/.local/lib/python3.8/site-packages/airflow/providers/amazon/aws/hooks/s3.py", line 89, in wrapper
    return func(*bound_args.args, **bound_args.kwargs)
  File "/home/airflow/.local/lib/python3.8/site-packages/airflow/providers/amazon/aws/hooks/s3.py", line 1082, in load_file
    client.upload_file(filename, bucket_name, key, ExtraArgs=extra_args, Config=self.transfer_config)
  File "/home/airflow/.local/lib/python3.8/site-packages/boto3/s3/inject.py", line 143, in upload_file
    return transfer.upload_file(
  File "/home/airflow/.local/lib/python3.8/site-packages/boto3/s3/transfer.py", line 292, in upload_file
    future.result()
  File "/home/airflow/.local/lib/python3.8/site-packages/s3transfer/futures.py", line 103, in result
    return self._coordinator.result()
  File "/home/airflow/.local/lib/python3.8/site-packages/s3transfer/futures.py", line 266, in result
    raise self._exception
  File "/home/airflow/.local/lib/python3.8/site-packages/s3transfer/tasks.py", line 269, in _main
    self._submit(transfer_future=transfer_future, **kwargs)
  File "/home/airflow/.local/lib/python3.8/site-packages/s3transfer/upload.py", line 591, in _submit
    upload_input_manager.provide_transfer_size(transfer_future)
  File "/home/airflow/.local/lib/python3.8/site-packages/s3transfer/upload.py", line 244, in provide_transfer_size
    self._osutil.get_file_size(transfer_future.meta.call_args.fileobj)
  File "/home/airflow/.local/lib/python3.8/site-packages/s3transfer/utils.py", line 247, in get_file_size
    return os.path.getsize(filename)
  File "/usr/local/lib/python3.8/genericpath.py", line 50, in getsize
    return os.stat(filename).st_size
FileNotFoundError: [Errno 2] No such file or directory: "<_io.TextIOWrapper name=19 mode='w' encoding='UTF-8'>"
[2023-12-05T14:25:37.381+0000] {taskinstance.py:1400} INFO - Marking task as UP_FOR_RETRY. dag_id=dag_with_hook_v4, task_id=upload_to_s3, execution_date=20231204T030000, start_date=20231205T142536, end_date=20231205T142537
[2023-12-05T14:25:37.410+0000] {standard_task_runner.py:104} ERROR - Failed to execute job 360 for task upload_to_s3 ([Errno 2] No such file or directory: "<_io.TextIOWrapper name=19 mode='w' encoding='UTF-8'>"; 18009)
[2023-12-05T14:25:37.450+0000] {local_task_job_runner.py:228} INFO - Task exited with return code 1
[2023-12-05T14:25:37.480+0000] {taskinstance.py:2778} INFO - 0 downstream tasks scheduled from follow-on schedule check
