[2023-12-05T09:42:34.069+0000] {taskinstance.py:1159} INFO - Dependencies all met for dep_context=non-requeueable deps ti=<TaskInstance: dag_with_python.get_sklearn scheduled__2023-12-04T00:00:00+00:00 [queued]>
[2023-12-05T09:42:34.084+0000] {taskinstance.py:1159} INFO - Dependencies all met for dep_context=requeueable deps ti=<TaskInstance: dag_with_python.get_sklearn scheduled__2023-12-04T00:00:00+00:00 [queued]>
[2023-12-05T09:42:34.085+0000] {taskinstance.py:1361} INFO - Starting attempt 2 of 6
[2023-12-05T09:42:34.113+0000] {taskinstance.py:1382} INFO - Executing <Task(PythonOperator): get_sklearn> on 2023-12-04 00:00:00+00:00
[2023-12-05T09:42:34.121+0000] {standard_task_runner.py:57} INFO - Started process 47310 to run task
[2023-12-05T09:42:34.126+0000] {standard_task_runner.py:84} INFO - Running: ['***', 'tasks', 'run', 'dag_with_python', 'get_sklearn', 'scheduled__2023-12-04T00:00:00+00:00', '--job-id', '306', '--raw', '--subdir', 'DAGS_FOLDER/dag_with_python.py', '--cfg-path', '/tmp/tmp_58os_79']
[2023-12-05T09:42:34.131+0000] {standard_task_runner.py:85} INFO - Job 306: Subtask get_sklearn
[2023-12-05T09:42:34.213+0000] {task_command.py:416} INFO - Running <TaskInstance: dag_with_python.get_sklearn scheduled__2023-12-04T00:00:00+00:00 [running]> on host a859eb4bf49d
[2023-12-05T09:42:34.370+0000] {taskinstance.py:1662} INFO - Exporting env vars: AIRFLOW_CTX_DAG_OWNER='debora' AIRFLOW_CTX_DAG_ID='dag_with_python' AIRFLOW_CTX_TASK_ID='get_sklearn' AIRFLOW_CTX_EXECUTION_DATE='2023-12-04T00:00:00+00:00' AIRFLOW_CTX_TRY_NUMBER='2' AIRFLOW_CTX_DAG_RUN_ID='scheduled__2023-12-04T00:00:00+00:00'
[2023-12-05T09:42:34.375+0000] {taskinstance.py:1937} ERROR - Task failed with exception
Traceback (most recent call last):
  File "/home/airflow/.local/lib/python3.8/site-packages/airflow/operators/python.py", line 192, in execute
    return_value = self.execute_callable()
  File "/home/airflow/.local/lib/python3.8/site-packages/airflow/operators/python.py", line 209, in execute_callable
    return self.python_callable(*self.op_args, **self.op_kwargs)
  File "/opt/airflow/dags/dag_with_python.py", line 13, in get_sklearn
    import sklearn
ModuleNotFoundError: No module named 'sklearn'
[2023-12-05T09:42:34.392+0000] {taskinstance.py:1400} INFO - Marking task as UP_FOR_RETRY. dag_id=dag_with_python, task_id=get_sklearn, execution_date=20231204T000000, start_date=20231205T094234, end_date=20231205T094234
[2023-12-05T09:42:34.421+0000] {standard_task_runner.py:104} ERROR - Failed to execute job 306 for task get_sklearn (No module named 'sklearn'; 47310)
[2023-12-05T09:42:34.461+0000] {local_task_job_runner.py:228} INFO - Task exited with return code 1
[2023-12-05T09:42:34.491+0000] {taskinstance.py:2778} INFO - 0 downstream tasks scheduled from follow-on schedule check
