[2023-12-05T14:29:31.125+0000] {taskinstance.py:1159} INFO - Dependencies all met for dep_context=non-requeueable deps ti=<TaskInstance: dag_with_hook_v4.upload_to_s3 manual__2023-12-05T14:29:29.627156+00:00 [queued]>
[2023-12-05T14:29:31.167+0000] {taskinstance.py:1159} INFO - Dependencies all met for dep_context=requeueable deps ti=<TaskInstance: dag_with_hook_v4.upload_to_s3 manual__2023-12-05T14:29:29.627156+00:00 [queued]>
[2023-12-05T14:29:31.168+0000] {taskinstance.py:1361} INFO - Starting attempt 1 of 6
[2023-12-05T14:29:31.191+0000] {taskinstance.py:1382} INFO - Executing <Task(PythonOperator): upload_to_s3> on 2023-12-05 14:29:29.627156+00:00
[2023-12-05T14:29:31.197+0000] {standard_task_runner.py:57} INFO - Started process 18401 to run task
[2023-12-05T14:29:31.202+0000] {standard_task_runner.py:84} INFO - Running: ['***', 'tasks', 'run', 'dag_with_hook_v4', 'upload_to_s3', 'manual__2023-12-05T14:29:29.627156+00:00', '--job-id', '362', '--raw', '--subdir', 'DAGS_FOLDER/dag_with_postgres_with_hook.py', '--cfg-path', '/tmp/tmpxjtdvl1_']
[2023-12-05T14:29:31.206+0000] {standard_task_runner.py:85} INFO - Job 362: Subtask upload_to_s3
[2023-12-05T14:29:31.277+0000] {task_command.py:416} INFO - Running <TaskInstance: dag_with_hook_v4.upload_to_s3 manual__2023-12-05T14:29:29.627156+00:00 [running]> on host 0c998a8be895
[2023-12-05T14:29:31.390+0000] {taskinstance.py:1662} INFO - Exporting env vars: AIRFLOW_CTX_DAG_OWNER='debora' AIRFLOW_CTX_DAG_ID='dag_with_hook_v4' AIRFLOW_CTX_TASK_ID='upload_to_s3' AIRFLOW_CTX_EXECUTION_DATE='2023-12-05T14:29:29.627156+00:00' AIRFLOW_CTX_TRY_NUMBER='1' AIRFLOW_CTX_DAG_RUN_ID='manual__2023-12-05T14:29:29.627156+00:00'
[2023-12-05T14:29:31.400+0000] {logging_mixin.py:154} WARNING - /home/***/.local/lib/python3.8/site-packages/***/utils/context.py:206 AirflowContextDeprecationWarning: Accessing 'execution_date' from the template is deprecated and will be removed in a future version. Please use 'data_interval_start' or 'logical_date' instead.
[2023-12-05T14:29:31.412+0000] {base.py:73} INFO - Using connection ID 'postgres_localhost' for task execution.
[2023-12-05T14:29:31.425+0000] {logging_mixin.py:154} INFO - connected to postgres
[2023-12-05T14:29:31.434+0000] {dag_with_postgres_with_hook.py:33} INFO - Saved get_orders_2023-12-05T14:29:29.627156+00:00
[2023-12-05T14:29:31.447+0000] {base.py:73} INFO - Using connection ID 'minio_conn_id' for task execution.
[2023-12-05T14:29:31.450+0000] {connection_wrapper.py:381} INFO - AWS Connection (conn_id='minio_conn_id', conn_type='aws') credentials retrieved from extra.
[2023-12-05T14:29:31.453+0000] {logging_mixin.py:154} WARNING - <string>:9 AirflowProviderDeprecationWarning: extra['host'] is deprecated and will be removed in a future release. Please set extra['endpoint_url'] instead
[2023-12-05T14:29:32.091+0000] {logging_mixin.py:154} WARNING - --- Logging error ---
[2023-12-05T14:29:32.093+0000] {logging_mixin.py:154} WARNING - Traceback (most recent call last):
[2023-12-05T14:29:32.094+0000] {logging_mixin.py:154} WARNING -   File "/usr/local/lib/python3.8/logging/__init__.py", line 1085, in emit
    msg = self.format(record)
[2023-12-05T14:29:32.095+0000] {logging_mixin.py:154} WARNING -   File "/usr/local/lib/python3.8/logging/__init__.py", line 929, in format
    return fmt.format(record)
[2023-12-05T14:29:32.096+0000] {logging_mixin.py:154} WARNING -   File "/usr/local/lib/python3.8/logging/__init__.py", line 668, in format
    record.message = record.getMessage()
[2023-12-05T14:29:32.097+0000] {logging_mixin.py:154} WARNING -   File "/usr/local/lib/python3.8/logging/__init__.py", line 373, in getMessage
    msg = msg % self.args
[2023-12-05T14:29:32.098+0000] {logging_mixin.py:154} WARNING - TypeError: not all arguments converted during string formatting
[2023-12-05T14:29:32.099+0000] {logging_mixin.py:154} WARNING - Call stack:
[2023-12-05T14:29:32.104+0000] {logging_mixin.py:154} WARNING -   File "/home/***/.local/bin/***", line 8, in <module>
    sys.exit(main())
[2023-12-05T14:29:32.105+0000] {logging_mixin.py:154} WARNING -   File "/home/***/.local/lib/python3.8/site-packages/***/__main__.py", line 57, in main
    args.func(args)
[2023-12-05T14:29:32.106+0000] {logging_mixin.py:154} WARNING -   File "/home/***/.local/lib/python3.8/site-packages/***/cli/cli_config.py", line 49, in command
    return func(*args, **kwargs)
[2023-12-05T14:29:32.106+0000] {logging_mixin.py:154} WARNING -   File "/home/***/.local/lib/python3.8/site-packages/***/utils/cli.py", line 114, in wrapper
    return f(*args, **kwargs)
[2023-12-05T14:29:32.107+0000] {logging_mixin.py:154} WARNING -   File "/home/***/.local/lib/python3.8/site-packages/***/utils/providers_configuration_loader.py", line 55, in wrapped_function
    return func(*args, **kwargs)
[2023-12-05T14:29:32.108+0000] {logging_mixin.py:154} WARNING -   File "/home/***/.local/lib/python3.8/site-packages/***/cli/commands/scheduler_command.py", line 85, in scheduler
    _run_scheduler_job(job_runner, skip_serve_logs=args.skip_serve_logs)
[2023-12-05T14:29:32.108+0000] {logging_mixin.py:154} WARNING -   File "/home/***/.local/lib/python3.8/site-packages/***/cli/commands/scheduler_command.py", line 47, in _run_scheduler_job
    run_job(job=job_runner.job, execute_callable=job_runner._execute)
[2023-12-05T14:29:32.109+0000] {logging_mixin.py:154} WARNING -   File "/home/***/.local/lib/python3.8/site-packages/***/utils/session.py", line 79, in wrapper
    return func(*args, session=session, **kwargs)
[2023-12-05T14:29:32.110+0000] {logging_mixin.py:154} WARNING -   File "/home/***/.local/lib/python3.8/site-packages/***/jobs/job.py", line 289, in run_job
    return execute_job(job, execute_callable=execute_callable)
[2023-12-05T14:29:32.110+0000] {logging_mixin.py:154} WARNING -   File "/home/***/.local/lib/python3.8/site-packages/***/jobs/job.py", line 318, in execute_job
    ret = execute_callable()
[2023-12-05T14:29:32.111+0000] {logging_mixin.py:154} WARNING -   File "/home/***/.local/lib/python3.8/site-packages/***/jobs/scheduler_job_runner.py", line 835, in _execute
    self.job.executor.start()
[2023-12-05T14:29:32.111+0000] {logging_mixin.py:154} WARNING -   File "/home/***/.local/lib/python3.8/site-packages/***/executors/local_executor.py", line 372, in start
    self.impl.start()
[2023-12-05T14:29:32.112+0000] {logging_mixin.py:154} WARNING -   File "/home/***/.local/lib/python3.8/site-packages/***/executors/local_executor.py", line 311, in start
    worker.start()
[2023-12-05T14:29:32.112+0000] {logging_mixin.py:154} WARNING -   File "/usr/local/lib/python3.8/multiprocessing/process.py", line 121, in start
    self._popen = self._Popen(self)
[2023-12-05T14:29:32.113+0000] {logging_mixin.py:154} WARNING -   File "/usr/local/lib/python3.8/multiprocessing/context.py", line 224, in _Popen
    return _default_context.get_context().Process._Popen(process_obj)
[2023-12-05T14:29:32.113+0000] {logging_mixin.py:154} WARNING -   File "/usr/local/lib/python3.8/multiprocessing/context.py", line 277, in _Popen
    return Popen(process_obj)
[2023-12-05T14:29:32.114+0000] {logging_mixin.py:154} WARNING -   File "/usr/local/lib/python3.8/multiprocessing/popen_fork.py", line 19, in __init__
    self._launch(process_obj)
[2023-12-05T14:29:32.114+0000] {logging_mixin.py:154} WARNING -   File "/usr/local/lib/python3.8/multiprocessing/popen_fork.py", line 75, in _launch
    code = process_obj._bootstrap(parent_sentinel=child_r)
[2023-12-05T14:29:32.115+0000] {logging_mixin.py:154} WARNING -   File "/usr/local/lib/python3.8/multiprocessing/process.py", line 315, in _bootstrap
    self.run()
[2023-12-05T14:29:32.115+0000] {logging_mixin.py:154} WARNING -   File "/home/***/.local/lib/python3.8/site-packages/***/executors/local_executor.py", line 77, in run
    return super().run()
[2023-12-05T14:29:32.116+0000] {logging_mixin.py:154} WARNING -   File "/usr/local/lib/python3.8/multiprocessing/process.py", line 108, in run
    self._target(*self._args, **self._kwargs)
[2023-12-05T14:29:32.116+0000] {logging_mixin.py:154} WARNING -   File "/home/***/.local/lib/python3.8/site-packages/***/executors/local_executor.py", line 201, in do_work
    self.execute_work(key=key, command=command)
[2023-12-05T14:29:32.117+0000] {logging_mixin.py:154} WARNING -   File "/home/***/.local/lib/python3.8/site-packages/***/executors/local_executor.py", line 94, in execute_work
    state = self._execute_work_in_fork(command)
[2023-12-05T14:29:32.117+0000] {logging_mixin.py:154} WARNING -   File "/home/***/.local/lib/python3.8/site-packages/***/executors/local_executor.py", line 134, in _execute_work_in_fork
    args.func(args)
[2023-12-05T14:29:32.118+0000] {logging_mixin.py:154} WARNING -   File "/home/***/.local/lib/python3.8/site-packages/***/cli/cli_config.py", line 49, in command
    return func(*args, **kwargs)
[2023-12-05T14:29:32.119+0000] {logging_mixin.py:154} WARNING -   File "/home/***/.local/lib/python3.8/site-packages/***/utils/cli.py", line 114, in wrapper
    return f(*args, **kwargs)
[2023-12-05T14:29:32.119+0000] {logging_mixin.py:154} WARNING -   File "/home/***/.local/lib/python3.8/site-packages/***/cli/commands/task_command.py", line 431, in task_run
    task_return_code = _run_task_by_selected_method(args, _dag, ti)
[2023-12-05T14:29:32.120+0000] {logging_mixin.py:154} WARNING -   File "/home/***/.local/lib/python3.8/site-packages/***/cli/commands/task_command.py", line 209, in _run_task_by_selected_method
    return _run_task_by_local_task_job(args, ti)
[2023-12-05T14:29:32.120+0000] {logging_mixin.py:154} WARNING -   File "/home/***/.local/lib/python3.8/site-packages/***/cli/commands/task_command.py", line 271, in _run_task_by_local_task_job
    ret = run_job(job=job_runner.job, execute_callable=job_runner._execute)
[2023-12-05T14:29:32.121+0000] {logging_mixin.py:154} WARNING -   File "/home/***/.local/lib/python3.8/site-packages/***/utils/session.py", line 79, in wrapper
    return func(*args, session=session, **kwargs)
[2023-12-05T14:29:32.121+0000] {logging_mixin.py:154} WARNING -   File "/home/***/.local/lib/python3.8/site-packages/***/jobs/job.py", line 289, in run_job
    return execute_job(job, execute_callable=execute_callable)
[2023-12-05T14:29:32.121+0000] {logging_mixin.py:154} WARNING -   File "/home/***/.local/lib/python3.8/site-packages/***/jobs/job.py", line 318, in execute_job
    ret = execute_callable()
[2023-12-05T14:29:32.122+0000] {logging_mixin.py:154} WARNING -   File "/home/***/.local/lib/python3.8/site-packages/***/jobs/local_task_job_runner.py", line 159, in _execute
    self.task_runner.start()
[2023-12-05T14:29:32.122+0000] {logging_mixin.py:154} WARNING -   File "/home/***/.local/lib/python3.8/site-packages/***/task/task_runner/standard_task_runner.py", line 45, in start
    self.process = self._start_by_fork()
[2023-12-05T14:29:32.123+0000] {logging_mixin.py:154} WARNING -   File "/home/***/.local/lib/python3.8/site-packages/***/task/task_runner/standard_task_runner.py", line 97, in _start_by_fork
    ret = args.func(args, dag=self.dag)
[2023-12-05T14:29:32.123+0000] {logging_mixin.py:154} WARNING -   File "/home/***/.local/lib/python3.8/site-packages/***/cli/cli_config.py", line 49, in command
    return func(*args, **kwargs)
[2023-12-05T14:29:32.124+0000] {logging_mixin.py:154} WARNING -   File "/home/***/.local/lib/python3.8/site-packages/***/utils/cli.py", line 114, in wrapper
    return f(*args, **kwargs)
[2023-12-05T14:29:32.124+0000] {logging_mixin.py:154} WARNING -   File "/home/***/.local/lib/python3.8/site-packages/***/cli/commands/task_command.py", line 431, in task_run
    task_return_code = _run_task_by_selected_method(args, _dag, ti)
[2023-12-05T14:29:32.124+0000] {logging_mixin.py:154} WARNING -   File "/home/***/.local/lib/python3.8/site-packages/***/cli/commands/task_command.py", line 211, in _run_task_by_selected_method
    return _run_raw_task(args, ti)
[2023-12-05T14:29:32.125+0000] {logging_mixin.py:154} WARNING -   File "/home/***/.local/lib/python3.8/site-packages/***/cli/commands/task_command.py", line 290, in _run_raw_task
    return ti._run_raw_task(
[2023-12-05T14:29:32.125+0000] {logging_mixin.py:154} WARNING -   File "/home/***/.local/lib/python3.8/site-packages/***/utils/session.py", line 79, in wrapper
    return func(*args, session=session, **kwargs)
[2023-12-05T14:29:32.126+0000] {logging_mixin.py:154} WARNING -   File "/home/***/.local/lib/python3.8/site-packages/***/models/taskinstance.py", line 1518, in _run_raw_task
    self._execute_task_with_callbacks(context, test_mode, session=session)
[2023-12-05T14:29:32.126+0000] {logging_mixin.py:154} WARNING -   File "/home/***/.local/lib/python3.8/site-packages/***/models/taskinstance.py", line 1681, in _execute_task_with_callbacks
    result = self._execute_task(context, task_orig)
[2023-12-05T14:29:32.127+0000] {logging_mixin.py:154} WARNING -   File "/home/***/.local/lib/python3.8/site-packages/***/models/taskinstance.py", line 1744, in _execute_task
    result = execute_callable(context=context, **execute_callable_kwargs)
[2023-12-05T14:29:32.127+0000] {logging_mixin.py:154} WARNING -   File "/home/***/.local/lib/python3.8/site-packages/***/operators/python.py", line 192, in execute
    return_value = self.execute_callable()
[2023-12-05T14:29:32.128+0000] {logging_mixin.py:154} WARNING -   File "/home/***/.local/lib/python3.8/site-packages/***/operators/python.py", line 209, in execute_callable
    return self.python_callable(*self.op_args, **self.op_kwargs)
[2023-12-05T14:29:32.128+0000] {logging_mixin.py:154} WARNING -   File "/opt/***/dags/dag_with_postgres_with_hook.py", line 41, in postgres_to_s3
    logging.info("Orders files have been pushed to s3", f.name)
[2023-12-05T14:29:32.128+0000] {logging_mixin.py:154} WARNING -   File "/usr/local/lib/python3.8/logging/__init__.py", line 2082, in info
    root.info(msg, *args, **kwargs)
[2023-12-05T14:29:32.129+0000] {logging_mixin.py:154} WARNING -   File "/usr/local/lib/python3.8/logging/__init__.py", line 1446, in info
    self._log(INFO, msg, args, **kwargs)
[2023-12-05T14:29:32.129+0000] {logging_mixin.py:154} WARNING -   File "/usr/local/lib/python3.8/logging/__init__.py", line 1589, in _log
    self.handle(record)
[2023-12-05T14:29:32.130+0000] {logging_mixin.py:154} WARNING -   File "/usr/local/lib/python3.8/logging/__init__.py", line 1599, in handle
    self.callHandlers(record)
[2023-12-05T14:29:32.130+0000] {logging_mixin.py:154} WARNING -   File "/usr/local/lib/python3.8/logging/__init__.py", line 1661, in callHandlers
    hdlr.handle(record)
[2023-12-05T14:29:32.131+0000] {logging_mixin.py:154} WARNING -   File "/usr/local/lib/python3.8/logging/__init__.py", line 954, in handle
    self.emit(record)
[2023-12-05T14:29:32.131+0000] {logging_mixin.py:154} WARNING -   File "/home/***/.local/lib/python3.8/site-packages/***/utils/log/file_task_handler.py", line 210, in emit
    self.handler.emit(record)
[2023-12-05T14:29:32.132+0000] {logging_mixin.py:154} WARNING - Message: 'Orders files have been pushed to s3'
Arguments: ('/tmp/tmp3ubr81q72023-12-05T14:29:29.627156+00:00',)
[2023-12-05T14:29:32.132+0000] {python.py:194} INFO - Done. Returned value was: None
[2023-12-05T14:29:32.144+0000] {taskinstance.py:1400} INFO - Marking task as SUCCESS. dag_id=dag_with_hook_v4, task_id=upload_to_s3, execution_date=20231205T142929, start_date=20231205T142931, end_date=20231205T142932
[2023-12-05T14:29:32.182+0000] {local_task_job_runner.py:228} INFO - Task exited with return code 0
[2023-12-05T14:29:32.203+0000] {taskinstance.py:2778} INFO - 0 downstream tasks scheduled from follow-on schedule check
