[2023-12-04T10:50:52.770+0000] {taskinstance.py:1159} INFO - Dependencies all met for dep_context=non-requeueable deps ti=<TaskInstance: dag_with_python_v4.get_name manual__2023-12-04T10:50:51.743921+00:00 [queued]>
[2023-12-04T10:50:52.802+0000] {taskinstance.py:1159} INFO - Dependencies all met for dep_context=requeueable deps ti=<TaskInstance: dag_with_python_v4.get_name manual__2023-12-04T10:50:51.743921+00:00 [queued]>
[2023-12-04T10:50:52.803+0000] {taskinstance.py:1361} INFO - Starting attempt 1 of 6
[2023-12-04T10:50:52.831+0000] {taskinstance.py:1382} INFO - Executing <Task(PythonOperator): get_name> on 2023-12-04 10:50:51.743921+00:00
[2023-12-04T10:50:52.836+0000] {standard_task_runner.py:57} INFO - Started process 57908 to run task
[2023-12-04T10:50:52.842+0000] {standard_task_runner.py:84} INFO - Running: ['***', 'tasks', 'run', 'dag_with_python_v4', 'get_name', 'manual__2023-12-04T10:50:51.743921+00:00', '--job-id', '21', '--raw', '--subdir', 'DAGS_FOLDER/created_dag_with_python.py', '--cfg-path', '/tmp/tmpc3xam4ro']
[2023-12-04T10:50:52.846+0000] {standard_task_runner.py:85} INFO - Job 21: Subtask get_name
[2023-12-04T10:50:52.915+0000] {task_command.py:416} INFO - Running <TaskInstance: dag_with_python_v4.get_name manual__2023-12-04T10:50:51.743921+00:00 [running]> on host a859eb4bf49d
[2023-12-04T10:50:53.038+0000] {taskinstance.py:1662} INFO - Exporting env vars: AIRFLOW_CTX_DAG_OWNER='debora' AIRFLOW_CTX_DAG_ID='dag_with_python_v4' AIRFLOW_CTX_TASK_ID='get_name' AIRFLOW_CTX_EXECUTION_DATE='2023-12-04T10:50:51.743921+00:00' AIRFLOW_CTX_TRY_NUMBER='1' AIRFLOW_CTX_DAG_RUN_ID='manual__2023-12-04T10:50:51.743921+00:00'
[2023-12-04T10:50:53.060+0000] {taskinstance.py:1937} ERROR - Task failed with exception
Traceback (most recent call last):
  File "/home/airflow/.local/lib/python3.8/site-packages/airflow/operators/python.py", line 192, in execute
    return_value = self.execute_callable()
  File "/home/airflow/.local/lib/python3.8/site-packages/airflow/operators/python.py", line 209, in execute_callable
    return self.python_callable(*self.op_args, **self.op_kwargs)
  File "/opt/airflow/dags/created_dag_with_python.py", line 19, in get_name
    ti.xcom_pus(key='last_name', value='Santos')
AttributeError: 'TaskInstance' object has no attribute 'xcom_pus'
[2023-12-04T10:50:53.076+0000] {taskinstance.py:1400} INFO - Marking task as UP_FOR_RETRY. dag_id=dag_with_python_v4, task_id=get_name, execution_date=20231204T105051, start_date=20231204T105052, end_date=20231204T105053
[2023-12-04T10:50:53.094+0000] {standard_task_runner.py:104} ERROR - Failed to execute job 21 for task get_name ('TaskInstance' object has no attribute 'xcom_pus'; 57908)
[2023-12-04T10:50:53.136+0000] {local_task_job_runner.py:228} INFO - Task exited with return code 1
[2023-12-04T10:50:53.168+0000] {taskinstance.py:2778} INFO - 0 downstream tasks scheduled from follow-on schedule check
