[2023-12-05T10:07:55.010+0000] {taskinstance.py:1159} INFO - Dependencies all met for dep_context=non-requeueable deps ti=<TaskInstance: dag_with_python_v11.get_matplotlib scheduled__2023-12-02T00:00:00+00:00 [queued]>
[2023-12-05T10:07:55.035+0000] {taskinstance.py:1159} INFO - Dependencies all met for dep_context=requeueable deps ti=<TaskInstance: dag_with_python_v11.get_matplotlib scheduled__2023-12-02T00:00:00+00:00 [queued]>
[2023-12-05T10:07:55.036+0000] {taskinstance.py:1361} INFO - Starting attempt 1 of 6
[2023-12-05T10:07:55.071+0000] {taskinstance.py:1382} INFO - Executing <Task(PythonOperator): get_matplotlib> on 2023-12-02 00:00:00+00:00
[2023-12-05T10:07:55.083+0000] {standard_task_runner.py:57} INFO - Started process 1897 to run task
[2023-12-05T10:07:55.090+0000] {standard_task_runner.py:84} INFO - Running: ['***', 'tasks', 'run', 'dag_with_python_v11', 'get_matplotlib', 'scheduled__2023-12-02T00:00:00+00:00', '--job-id', '325', '--raw', '--subdir', 'DAGS_FOLDER/dag_with_python.py', '--cfg-path', '/tmp/tmpg0bpkj0c']
[2023-12-05T10:07:55.097+0000] {standard_task_runner.py:85} INFO - Job 325: Subtask get_matplotlib
[2023-12-05T10:07:55.209+0000] {task_command.py:416} INFO - Running <TaskInstance: dag_with_python_v11.get_matplotlib scheduled__2023-12-02T00:00:00+00:00 [running]> on host ab160eb3107c
[2023-12-05T10:07:55.409+0000] {taskinstance.py:1662} INFO - Exporting env vars: AIRFLOW_CTX_DAG_OWNER='debora' AIRFLOW_CTX_DAG_ID='dag_with_python_v11' AIRFLOW_CTX_TASK_ID='get_matplotlib' AIRFLOW_CTX_EXECUTION_DATE='2023-12-02T00:00:00+00:00' AIRFLOW_CTX_TRY_NUMBER='1' AIRFLOW_CTX_DAG_RUN_ID='scheduled__2023-12-02T00:00:00+00:00'
[2023-12-05T10:07:55.413+0000] {taskinstance.py:1937} ERROR - Task failed with exception
Traceback (most recent call last):
  File "/home/airflow/.local/lib/python3.8/site-packages/airflow/operators/python.py", line 192, in execute
    return_value = self.execute_callable()
  File "/home/airflow/.local/lib/python3.8/site-packages/airflow/operators/python.py", line 209, in execute_callable
    return self.python_callable(*self.op_args, **self.op_kwargs)
  File "/opt/airflow/dags/dag_with_python.py", line 17, in get_matplotlib
    import matplotlib
ModuleNotFoundError: No module named 'matplotlib'
[2023-12-05T10:07:55.437+0000] {taskinstance.py:1400} INFO - Marking task as UP_FOR_RETRY. dag_id=dag_with_python_v11, task_id=get_matplotlib, execution_date=20231202T000000, start_date=20231205T100755, end_date=20231205T100755
[2023-12-05T10:07:55.464+0000] {standard_task_runner.py:104} ERROR - Failed to execute job 325 for task get_matplotlib (No module named 'matplotlib'; 1897)
[2023-12-05T10:07:55.507+0000] {local_task_job_runner.py:228} INFO - Task exited with return code 1
[2023-12-05T10:07:55.549+0000] {taskinstance.py:2778} INFO - 0 downstream tasks scheduled from follow-on schedule check
