[2023-12-04T10:44:44.727+0000] {taskinstance.py:1159} INFO - Dependencies all met for dep_context=non-requeueable deps ti=<TaskInstance: dag_with_python_v3.greet manual__2023-12-04T10:44:42.641422+00:00 [queued]>
[2023-12-04T10:44:44.745+0000] {taskinstance.py:1159} INFO - Dependencies all met for dep_context=requeueable deps ti=<TaskInstance: dag_with_python_v3.greet manual__2023-12-04T10:44:42.641422+00:00 [queued]>
[2023-12-04T10:44:44.746+0000] {taskinstance.py:1361} INFO - Starting attempt 1 of 6
[2023-12-04T10:44:44.776+0000] {taskinstance.py:1382} INFO - Executing <Task(PythonOperator): greet> on 2023-12-04 10:44:42.641422+00:00
[2023-12-04T10:44:44.781+0000] {standard_task_runner.py:57} INFO - Started process 57690 to run task
[2023-12-04T10:44:44.786+0000] {standard_task_runner.py:84} INFO - Running: ['***', 'tasks', 'run', 'dag_with_python_v3', 'greet', 'manual__2023-12-04T10:44:42.641422+00:00', '--job-id', '14', '--raw', '--subdir', 'DAGS_FOLDER/created_dag_with_python.py', '--cfg-path', '/tmp/tmp889eeg9w']
[2023-12-04T10:44:44.791+0000] {standard_task_runner.py:85} INFO - Job 14: Subtask greet
[2023-12-04T10:44:44.880+0000] {task_command.py:416} INFO - Running <TaskInstance: dag_with_python_v3.greet manual__2023-12-04T10:44:42.641422+00:00 [running]> on host a859eb4bf49d
[2023-12-04T10:44:45.017+0000] {taskinstance.py:1662} INFO - Exporting env vars: AIRFLOW_CTX_DAG_OWNER='debora' AIRFLOW_CTX_DAG_ID='dag_with_python_v3' AIRFLOW_CTX_TASK_ID='greet' AIRFLOW_CTX_EXECUTION_DATE='2023-12-04T10:44:42.641422+00:00' AIRFLOW_CTX_TRY_NUMBER='1' AIRFLOW_CTX_DAG_RUN_ID='manual__2023-12-04T10:44:42.641422+00:00'
[2023-12-04T10:44:45.018+0000] {taskinstance.py:1937} ERROR - Task failed with exception
Traceback (most recent call last):
  File "/home/airflow/.local/lib/python3.8/site-packages/airflow/operators/python.py", line 192, in execute
    return_value = self.execute_callable()
  File "/home/airflow/.local/lib/python3.8/site-packages/airflow/operators/python.py", line 209, in execute_callable
    return self.python_callable(*self.op_args, **self.op_kwargs)
  File "/opt/airflow/dags/created_dag_with_python.py", line 12, in greet
    name = ti.xcoms_pull(task_ids='get_name')
AttributeError: 'TaskInstance' object has no attribute 'xcoms_pull'
[2023-12-04T10:44:45.034+0000] {taskinstance.py:1400} INFO - Marking task as UP_FOR_RETRY. dag_id=dag_with_python_v3, task_id=greet, execution_date=20231204T104442, start_date=20231204T104444, end_date=20231204T104445
[2023-12-04T10:44:45.054+0000] {standard_task_runner.py:104} ERROR - Failed to execute job 14 for task greet ('TaskInstance' object has no attribute 'xcoms_pull'; 57690)
[2023-12-04T10:44:45.081+0000] {local_task_job_runner.py:228} INFO - Task exited with return code 1
[2023-12-04T10:44:45.109+0000] {taskinstance.py:2778} INFO - 0 downstream tasks scheduled from follow-on schedule check
